<?xml version="1.0" encoding="utf-8"?>
<!-- This URDF was automatically created by SolidWorks to URDF Exporter! Originally created by Stephen Brawner (brawner@gmail.com) 
     Commit Version: 1.5.1-0-g916b5db  Build Version: 1.5.7152.31018
     For more information, please see http://wiki.ros.org/sw_urdf_exporter -->
<robot
  name="SUBO3">
  <link
    name="UPPER_BODY_LINK">
    <inertial>
      <origin
        xyz="-0.00121613662788025 0.000362936481331684 0.0632689665914584"
        rpy="0 0 0" />
      <mass
        value="6.0033600020323" />
      <inertia
        ixx="0.0614305206865318"
        ixy="-2.25482669217692E-05"
        ixz="0.000723458294316814"
        iyy="0.0352319881960098"
        iyz="-0.000583323009420148"
        izz="0.0508033442051633" />
    </inertial>
    <visual>
      <origin
        xyz="0 0 0"
        rpy="0 0 0" />
      <geometry>
        <mesh
          filename="package://SUBO3/meshes/UPPER_BODY_LINK.STL" />
      </geometry>
      <material
        name="">
        <color
          rgba="0.752941176470588 0.752941176470588 0.752941176470588 1" />
      </material>
    </visual>
    <collision>
      <origin
        xyz="0 0 0"
        rpy="0 0 0" />
      <geometry>
        <mesh
          filename="package://SUBO3/meshes/UPPER_BODY_LINK.STL" />
      </geometry>
    </collision>
  </link>
  <link
    name="PELVIS_LINK">
    <inertial>
      <origin
        xyz="-0.015397 -3.7188E-06 -0.023829"
        rpy="0 0 0" />
      <mass
        value="2.4074" />
      <inertia
        ixx="0.01017"
        ixy="-1.4807E-06"
        ixz="9.2051E-05"
        iyy="0.0037161"
        iyz="3.9097E-07"
        izz="0.010827" />
    </inertial>
    <visual>
      <origin
        xyz="0 0 0"
        rpy="0 0 0" />
      <geometry>
        <mesh
          filename="package://SUBO3/meshes/PELVIS_LINK.STL" />
      </geometry>
      <material
        name="">
        <color
          rgba="0.75294 0.75294 0.75294 1" />
      </material>
    </visual>
    <collision>
      <origin
        xyz="0 0 0"
        rpy="0 0 0" />
      <geometry>
        <mesh
          filename="package://SUBO3/meshes/PELVIS_LINK.STL" />
      </geometry>
    </collision>
  </link>
  <joint
    name="PELVIS_JOINT"
    type="continuous">
    <origin
      xyz="0.021036 0 -0.04"
      rpy="0 0 0" />
    <parent
      link="UPPER_BODY_LINK" />
    <child
      link="PELVIS_LINK" />
    <axis
      xyz="0 0 0" />
  </joint>
  <link
    name="R_PELVIS_YAW_LINK">
    <inertial>
      <origin
        xyz="-0.0266159194797621 -0.00622707166856511 -0.0280687606149805"
        rpy="0 0 0" />
      <mass
        value="0.530103422401833" />
      <inertia
        ixx="0.000418701653694017"
        ixy="5.24777018034658E-06"
        ixz="-0.000133156991798303"
        iyy="0.00100064820216593"
        iyz="1.79739812482645E-05"
        izz="0.000820265805418251" />
    </inertial>
    <visual>
      <origin
        xyz="0 0 0"
        rpy="0 0 0" />
      <geometry>
        <mesh
          filename="package://SUBO3/meshes/R_PELVIS_YAW_LINK.STL" />
      </geometry>
      <material
        name="">
        <color
          rgba="0.752941176470588 0.752941176470588 0.752941176470588 1" />
      </material>
    </visual>
    <collision>
      <origin
        xyz="0 0 0"
        rpy="0 0 0" />
      <geometry>
        <mesh
          filename="package://SUBO3/meshes/R_PELVIS_YAW_LINK.STL" />
      </geometry>
    </collision>
  </link>
  <joint
    name="R_PELVIS_YAW_JOINT"
    type="continuous">
    <origin
      xyz="0 0.07 -0.075"
      rpy="0 0 0" />
    <parent
      link="PELVIS_LINK" />
    <child
      link="R_PELVIS_YAW_LINK" />
    <axis
      xyz="0 0 -1" />
    <limit
      lower="0"
      upper="0"
      effort="0"
      velocity="0" />
  </joint>
  <link
    name="R_PELVIS_ROLL_LINK">
    <inertial>
      <origin
        xyz="0.044125 0.01295 -2.4763E-05"
        rpy="0 0 0" />
      <mass
        value="0.92744" />
      <inertia
        ixx="0.00075826"
        ixy="-0.00021022"
        ixz="-1.847E-06"
        iyy="0.0010831"
        iyz="1.1233E-06"
        izz="0.0014423" />
    </inertial>
    <visual>
      <origin
        xyz="0 0 0"
        rpy="0 0 0" />
      <geometry>
        <mesh
          filename="package://SUBO3/meshes/R_PELVIS_ROLL_LINK.STL" />
      </geometry>
      <material
        name="">
        <color
          rgba="0.75294 0.75294 0.75294 1" />
      </material>
    </visual>
    <collision>
      <origin
        xyz="0 0 0"
        rpy="0 0 0" />
      <geometry>
        <mesh
          filename="package://SUBO3/meshes/R_PELVIS_ROLL_LINK.STL" />
      </geometry>
    </collision>
  </link>
  <joint
    name="R_PELVIS_ROLL_JOINT"
    type="continuous">
    <origin
      xyz="-0.06225 0 -0.074"
      rpy="0 0 0" />
    <parent
      link="R_PELVIS_YAW_LINK" />
    <child
      link="R_PELVIS_ROLL_LINK" />
    <axis
      xyz="1 0 0" />
    <limit
      lower="0"
      upper="0"
      effort="0"
      velocity="0" />
  </joint>
  <link
    name="R_PELVIS_PITCH_LINK">
    <inertial>
      <origin
        xyz="0.00473823664974571 -0.0348382774347742 -0.132461445473797"
        rpy="0 0 0" />
      <mass
        value="1.38598662239796" />
      <inertia
        ixx="0.0103150855388473"
        ixy="-1.64551460984081E-05"
        ixz="0.000216699945123139"
        iyy="0.00897984225192533"
        iyz="-0.000199389058493975"
        izz="0.0023718641125456" />
    </inertial>
    <visual>
      <origin
        xyz="0 0 0"
        rpy="0 0 0" />
      <geometry>
        <mesh
          filename="package://SUBO3/meshes/R_PELVIS_PITCH_LINK.STL" />
      </geometry>
      <material
        name="">
        <color
          rgba="0.752941176470588 0.752941176470588 0.752941176470588 1" />
      </material>
    </visual>
    <collision>
      <origin
        xyz="0 0 0"
        rpy="0 0 0" />
      <geometry>
        <mesh
          filename="package://SUBO3/meshes/R_PELVIS_PITCH_LINK.STL" />
      </geometry>
    </collision>
  </link>
  <joint
    name="R_PELVIS_PITCH_JOINT"
    type="continuous">
    <origin
      xyz="0.062 0.049 0"
      rpy="0 0 0" />
    <parent
      link="R_PELVIS_ROLL_LINK" />
    <child
      link="R_PELVIS_PITCH_LINK" />
    <axis
      xyz="0 -1 0" />
    <limit
      lower="0"
      upper="0"
      effort="0"
      velocity="0" />
  </joint>
  <link
    name="R_KNEE_PITCH_LINK">
    <inertial>
      <origin
        xyz="0.00011069 -0.029891 -0.070094"
        rpy="0 0 0" />
      <mass
        value="1.4709" />
      <inertia
        ixx="0.011839"
        ixy="1.5237E-05"
        ixz="-3.1809E-05"
        iyy="0.010754"
        iyz="-0.00064188"
        izz="0.0020508" />
    </inertial>
    <visual>
      <origin
        xyz="0 0 0"
        rpy="0 0 0" />
      <geometry>
        <mesh
          filename="package://SUBO3/meshes/R_KNEE_PITCH_LINK.STL" />
      </geometry>
      <material
        name="">
        <color
          rgba="0.75294 0.75294 0.75294 1" />
      </material>
    </visual>
    <collision>
      <origin
        xyz="0 0 0"
        rpy="0 0 0" />
      <geometry>
        <mesh
          filename="package://SUBO3/meshes/R_KNEE_PITCH_LINK.STL" />
      </geometry>
    </collision>
  </link>
  <joint
    name="R_KNEE_PITCH_JOINT"
    type="continuous">
    <origin
      xyz="0 0 -0.25"
      rpy="0 0 0" />
    <parent
      link="R_PELVIS_PITCH_LINK" />
    <child
      link="R_KNEE_PITCH_LINK" />
    <axis
      xyz="0 -1 0" />
    <limit
      lower="0"
      upper="0"
      effort="0"
      velocity="0" />
  </joint>
  <link
    name="R_ANKLE_PITCH_LINK">
    <inertial>
      <origin
        xyz="-0.013217 -0.041931 0.010133"
        rpy="0 0 0" />
      <mass
        value="1.2402" />
      <inertia
        ixx="0.0014248"
        ixy="-0.00014179"
        ixz="-3.7258E-05"
        iyy="0.0016907"
        iyz="0.00026597"
        izz="0.0018283" />
    </inertial>
    <visual>
      <origin
        xyz="0 0 0"
        rpy="0 0 0" />
      <geometry>
        <mesh
          filename="package://SUBO3/meshes/R_ANKLE_PITCH_LINK.STL" />
      </geometry>
      <material
        name="">
        <color
          rgba="0.75294 0.75294 0.75294 1" />
      </material>
    </visual>
    <collision>
      <origin
        xyz="0 0 0"
        rpy="0 0 0" />
      <geometry>
        <mesh
          filename="package://SUBO3/meshes/R_ANKLE_PITCH_LINK.STL" />
      </geometry>
    </collision>
  </link>
  <joint
    name="R_ANKLE_PITCH_JOINT"
    type="continuous">
    <origin
      xyz="0 0 -0.250000000000001"
      rpy="0 0 0" />
    <parent
      link="R_KNEE_PITCH_LINK" />
    <child
      link="R_ANKLE_PITCH_LINK" />
    <axis
      xyz="0 1 0" />
    <limit
      lower="0"
      upper="0"
      effort="0"
      velocity="0" />
  </joint>
  <link
    name="R_ANKLE_ROLL_LINK">
    <inertial>
      <origin
        xyz="0.0519072237773094 9.5062846483529E-16 -0.0264500245181195"
        rpy="0 0 0" />
      <mass
        value="0.274125500097104" />
      <inertia
        ixx="0.000225695352796775"
        ixy="-2.89043640503426E-17"
        ixz="6.97268513881213E-05"
        iyy="0.000785347726786842"
        iyz="3.59132440515167E-17"
        izz="0.000665543446851336" />
    </inertial>
    <visual>
      <origin
        xyz="0 0 0"
        rpy="0 0 0" />
      <geometry>
        <mesh
          filename="package://SUBO3/meshes/R_ANKLE_ROLL_LINK.STL" />
      </geometry>
      <material
        name="">
        <color
          rgba="0.752941176470588 0.752941176470588 0.752941176470588 1" />
      </material>
    </visual>
    <collision>
      <origin
        xyz="0 0 0"
        rpy="0 0 0" />
      <geometry>
        <mesh
          filename="package://SUBO3/meshes/R_ANKLE_ROLL_LINK.STL" />
      </geometry>
    </collision>
  </link>
  <joint
    name="R_ANKLE_ROLL_LINK"
    type="continuous">
    <origin
      xyz="-0.0609999999999998 -0.0489999999999999 0"
      rpy="0 0 0" />
    <parent
      link="R_ANKLE_PITCH_LINK" />
    <child
      link="R_ANKLE_ROLL_LINK" />
    <axis
      xyz="1 0 0" />
    <limit
      lower="0"
      upper="0"
      effort="0"
      velocity="0" />
  </joint>
  <link
    name="R_TORQUE_SENSOR_LINK">
    <inertial>
      <origin
        xyz="-0.000210746470182037 -0.000365068024424153 -0.00737652444410875"
        rpy="0 0 0" />
      <mass
        value="0.15369584473392" />
      <inertia
        ixx="8.39930706319288E-05"
        ixy="1.03002759760772E-06"
        ixz="3.64439977153939E-08"
        iyy="8.51827167616226E-05"
        iyz="6.30861990951583E-08"
        izz="0.000146735830034092" />
    </inertial>
    <visual>
      <origin
        xyz="0 0 0"
        rpy="0 0 0" />
      <geometry>
        <mesh
          filename="package://SUBO3/meshes/R_TORQUE_SENSOR_LINK.STL" />
      </geometry>
      <material
        name="">
        <color
          rgba="0.47843137254902 0.533333333333333 0.549019607843137 1" />
      </material>
    </visual>
    <collision>
      <origin
        xyz="0 0 0"
        rpy="0 0 0" />
      <geometry>
        <mesh
          filename="package://SUBO3/meshes/R_TORQUE_SENSOR_LINK.STL" />
      </geometry>
    </collision>
  </link>
  <joint
    name="R_TORQUE_SENSOR_JOINT"
    type="continuous">
    <origin
      xyz="0.062 0 -0.067"
      rpy="0 0 0" />
    <parent
      link="R_ANKLE_ROLL_LINK" />
    <child
      link="R_TORQUE_SENSOR_LINK" />
    <axis
      xyz="0 0 0" />
  </joint>
  <link
    name="R_FOOTPAD_LINK">
    <inertial>
      <origin
        xyz="0.0238467724113604 0.0101854780839428 -0.00327900727596753"
        rpy="0 0 0" />
      <mass
        value="0.389644381256943" />
      <inertia
        ixx="0.00049867478946717"
        ixy="6.00381907308722E-07"
        ixz="-2.38601358453508E-06"
        iyy="0.00113946165916835"
        iyz="-2.72583274330472E-07"
        izz="0.00162669448381451" />
    </inertial>
    <visual>
      <origin
        xyz="0 0 0"
        rpy="0 0 0" />
      <geometry>
        <mesh
          filename="package://SUBO3/meshes/R_FOOTPAD_LINK.STL" />
      </geometry>
      <material
        name="">
        <color
          rgba="0.752941176470588 0.752941176470588 0.752941176470588 1" />
      </material>
    </visual>
    <collision>
      <origin
        xyz="0 0 0"
        rpy="0 0 0" />
      <geometry>
        <mesh
          filename="package://SUBO3/meshes/R_FOOTPAD_LINK.STL" />
      </geometry>
    </collision>
  </link>
  <joint
    name="R_FOOTPAD_JOINT"
    type="continuous">
    <origin
      xyz="0 0 -0.024"
      rpy="0 0 0" />
    <parent
      link="R_TORQUE_SENSOR_LINK" />
    <child
      link="R_FOOTPAD_LINK" />
    <axis
      xyz="0 0 0" />
  </joint>
  <link
    name="R_LEG_IMU_LINK">
    <inertial>
      <origin
        xyz="0.000401989131834257 4.55636593021461E-05 0.00947601172535706"
        rpy="0 0 0" />
      <mass
        value="0.0368510660072014" />
      <inertia
        ixx="9.41068323673257E-06"
        ixy="3.11242579613717E-08"
        ixz="9.51931900260357E-08"
        iyy="9.15702253125901E-06"
        iyz="1.07897197579423E-08"
        izz="1.61909985527922E-05" />
    </inertial>
    <visual>
      <origin
        xyz="0 0 0"
        rpy="0 0 0" />
      <geometry>
        <mesh
          filename="package://SUBO3/meshes/R_LEG_IMU_LINK.STL" />
      </geometry>
      <material
        name="">
        <color
          rgba="0.00784313725490196 0.454901960784314 0.0980392156862745 1" />
      </material>
    </visual>
    <collision>
      <origin
        xyz="0 0 0"
        rpy="0 0 0" />
      <geometry>
        <mesh
          filename="package://SUBO3/meshes/R_LEG_IMU_LINK.STL" />
      </geometry>
    </collision>
  </link>
  <joint
    name="R_LEG_IMU_JOINT"
    type="continuous">
    <origin
      xyz="0.0785 0 0.003"
      rpy="0 0 0" />
    <parent
      link="R_FOOTPAD_LINK" />
    <child
      link="R_LEG_IMU_LINK" />
    <axis
      xyz="0 0 0" />
  </joint>
  <link
    name="L_PELVIS_YAW_LINK">
    <inertial>
      <origin
        xyz="-0.0265992174097636 0.00621733561950243 -0.0280670157677253"
        rpy="0 0 0" />
      <mass
        value="0.529177042283365" />
      <inertia
        ixx="0.000418436362803153"
        ixy="-5.71520135782746E-06"
        ixz="-0.000133777282387252"
        iyy="0.000997903435296154"
        iyz="-1.78719207361939E-05"
        izz="0.000817579542112976" />
    </inertial>
    <visual>
      <origin
        xyz="0 0 0"
        rpy="0 0 0" />
      <geometry>
        <mesh
          filename="package://SUBO3/meshes/L_PELVIS_YAW_LINK.STL" />
      </geometry>
      <material
        name="">
        <color
          rgba="0.752941176470588 0.752941176470588 0.752941176470588 1" />
      </material>
    </visual>
    <collision>
      <origin
        xyz="0 0 0"
        rpy="0 0 0" />
      <geometry>
        <mesh
          filename="package://SUBO3/meshes/L_PELVIS_YAW_LINK.STL" />
      </geometry>
    </collision>
  </link>
  <joint
    name="L_PELVIS_YAW_JOINT"
    type="continuous">
    <origin
      xyz="0 -0.07 -0.0749999999999992"
      rpy="0 0 0" />
    <parent
      link="PELVIS_LINK" />
    <child
      link="L_PELVIS_YAW_LINK" />
    <axis
      xyz="0 0 -1" />
    <limit
      lower="0"
      upper="0"
      effort="0"
      velocity="0" />
  </joint>
  <link
    name="L_PELVIS_ROLL_LINK">
    <inertial>
      <origin
        xyz="0.0436595716549452 -0.0133299225119321 -2.5133329525695E-05"
        rpy="0 0 0" />
      <mass
        value="0.912484667273741" />
      <inertia
        ixx="0.00074658332791256"
        ixy="0.000218625717124259"
        ixz="-1.83821114708385E-06"
        iyy="0.00106600610511238"
        iyz="-1.11196448498299E-06"
        izz="0.00141402720848758" />
    </inertial>
    <visual>
      <origin
        xyz="0 0 0"
        rpy="0 0 0" />
      <geometry>
        <mesh
          filename="package://SUBO3/meshes/L_PELVIS_ROLL_LINK.STL" />
      </geometry>
      <material
        name="">
        <color
          rgba="0.752941176470588 0.752941176470588 0.752941176470588 1" />
      </material>
    </visual>
    <collision>
      <origin
        xyz="0 0 0"
        rpy="0 0 0" />
      <geometry>
        <mesh
          filename="package://SUBO3/meshes/L_PELVIS_ROLL_LINK.STL" />
      </geometry>
    </collision>
  </link>
  <joint
    name="L_PELVIS_ROLL_JOINT"
    type="continuous">
    <origin
      xyz="-0.0622500000000003 0 -0.0740000000000007"
      rpy="0 0 0" />
    <parent
      link="L_PELVIS_YAW_LINK" />
    <child
      link="L_PELVIS_ROLL_LINK" />
    <axis
      xyz="-1 0 0" />
    <limit
      lower="0"
      upper="0"
      effort="0"
      velocity="0" />
  </joint>
  <link
    name="L_PELVIS_PITCH_LINK">
    <inertial>
      <origin
        xyz="0.00474029430050671 0.0348586483431658 -0.132488290291745"
        rpy="0 0 0" />
      <mass
        value="1.38538595091799" />
      <inertia
        ixx="0.0103114488482723"
        ixy="1.65886747891437E-05"
        ixz="0.000216521428778541"
        iyy="0.00897752223201723"
        iyz="0.000197642452339918"
        izz="0.00237052106188585" />
    </inertial>
    <visual>
      <origin
        xyz="0 0 0"
        rpy="0 0 0" />
      <geometry>
        <mesh
          filename="package://SUBO3/meshes/L_PELVIS_PITCH_LINK.STL" />
      </geometry>
      <material
        name="">
        <color
          rgba="0.752941176470588 0.752941176470588 0.752941176470588 1" />
      </material>
    </visual>
    <collision>
      <origin
        xyz="0 0 0"
        rpy="0 0 0" />
      <geometry>
        <mesh
          filename="package://SUBO3/meshes/L_PELVIS_PITCH_LINK.STL" />
      </geometry>
    </collision>
  </link>
  <joint
    name="L_PELVIS_PITCH_JOINT"
    type="continuous">
    <origin
      xyz="0.0619999999999986 -0.0489999999999418 0"
      rpy="0 0 0" />
    <parent
      link="L_PELVIS_ROLL_LINK" />
    <child
      link="L_PELVIS_PITCH_LINK" />
    <axis
      xyz="0 -1 0" />
    <limit
      lower="0"
      upper="0"
      effort="0"
      velocity="0" />
  </joint>
  <link
    name="L_KNEE_PITCH_LINK">
    <inertial>
      <origin
        xyz="0.000118888864164751 0.0299031716841409 -0.0701044353157416"
        rpy="0 0 0" />
      <mass
        value="1.46957620591496" />
      <inertia
        ixx="0.0118306421158916"
        ixy="-1.4718986276115E-05"
        ixz="-3.07656798720871E-05"
        iyy="0.0107461567310813"
        iyz="0.000643982796816516"
        izz="0.00204956077141715" />
    </inertial>
    <visual>
      <origin
        xyz="0 0 0"
        rpy="0 0 0" />
      <geometry>
        <mesh
          filename="package://SUBO3/meshes/L_KNEE_PITCH_LINK.STL" />
      </geometry>
      <material
        name="">
        <color
          rgba="0.752941176470588 0.752941176470588 0.752941176470588 1" />
      </material>
    </visual>
    <collision>
      <origin
        xyz="0 0 0"
        rpy="0 0 0" />
      <geometry>
        <mesh
          filename="package://SUBO3/meshes/L_KNEE_PITCH_LINK.STL" />
      </geometry>
    </collision>
  </link>
  <joint
    name="L_KNEE_PITCH_JOINT"
    type="continuous">
    <origin
      xyz="0 0 -0.249999999999997"
      rpy="0 0 0" />
    <parent
      link="L_PELVIS_PITCH_LINK" />
    <child
      link="L_KNEE_PITCH_LINK" />
    <axis
      xyz="0 -1 0" />
    <limit
      lower="0"
      upper="0"
      effort="0"
      velocity="0" />
  </joint>
  <link
    name="L_ANKLE_PITCH_LINK">
    <inertial>
      <origin
        xyz="-0.0132731832093409 0.041921041445987 0.0101315541870917"
        rpy="0 0 0" />
      <mass
        value="1.23810021571121" />
      <inertia
        ixx="0.00142361380320495"
        ixy="0.00014271718494148"
        ixz="-3.68757271246088E-05"
        iyy="0.00168717484907606"
        iyz="-0.000265595693829005"
        izz="0.00182483766271009" />
    </inertial>
    <visual>
      <origin
        xyz="0 0 0"
        rpy="0 0 0" />
      <geometry>
        <mesh
          filename="package://SUBO3/meshes/L_ANKLE_PITCH_LINK.STL" />
      </geometry>
      <material
        name="">
        <color
          rgba="0.752941176470588 0.752941176470588 0.752941176470588 1" />
      </material>
    </visual>
    <collision>
      <origin
        xyz="0 0 0"
        rpy="0 0 0" />
      <geometry>
        <mesh
          filename="package://SUBO3/meshes/L_ANKLE_PITCH_LINK.STL" />
      </geometry>
    </collision>
  </link>
  <joint
    name="L_ANKLE_PITCH_JOINT"
    type="continuous">
    <origin
      xyz="0 0 -0.250000000000002"
      rpy="0 0 0" />
    <parent
      link="L_KNEE_PITCH_LINK" />
    <child
      link="L_ANKLE_PITCH_LINK" />
    <axis
      xyz="0 1 0" />
    <limit
      lower="0"
      upper="0"
      effort="0"
      velocity="0" />
  </joint>
  <link
    name="L_ANKLE_ROLL_LINK">
    <inertial>
      <origin
        xyz="0.051907223777426 1.1518563880486E-15 -0.0264500245181492"
        rpy="0 0 0" />
      <mass
        value="0.274125500095123" />
      <inertia
        ixx="0.000225695352794553"
        ixy="2.15311540027307E-17"
        ixz="6.9726851386544E-05"
        iyy="0.000785347726778681"
        iyz="-2.15152191954105E-17"
        izz="0.000665543446844135" />
    </inertial>
    <visual>
      <origin
        xyz="0 0 0"
        rpy="0 0 0" />
      <geometry>
        <mesh
          filename="package://SUBO3/meshes/L_ANKLE_ROLL_LINK.STL" />
      </geometry>
      <material
        name="">
        <color
          rgba="0.752941176470588 0.752941176470588 0.752941176470588 1" />
      </material>
    </visual>
    <collision>
      <origin
        xyz="0 0 0"
        rpy="0 0 0" />
      <geometry>
        <mesh
          filename="package://SUBO3/meshes/L_ANKLE_ROLL_LINK.STL" />
      </geometry>
    </collision>
  </link>
  <joint
    name="L_ANKLE_ROLL_LINK"
    type="continuous">
    <origin
      xyz="-0.0610000000001195 0.0490000000004446 0"
      rpy="0 0 0" />
    <parent
      link="L_ANKLE_PITCH_LINK" />
    <child
      link="L_ANKLE_ROLL_LINK" />
    <axis
      xyz="-1 0 0" />
    <limit
      lower="0"
      upper="0"
      effort="0"
      velocity="0" />
  </joint>
  <link
    name="L_TORQUE_SENSOR_LINK">
    <inertial>
      <origin
        xyz="-0.000211059448215804 -0.000365563003641059 -0.00737662024071906"
        rpy="0 0 0" />
      <mass
        value="0.153697087859566" />
      <inertia
        ixx="8.39954225461241E-05"
        ixy="1.0296965698122E-06"
        ixz="3.71349717886691E-08"
        iyy="8.51833279576377E-05"
        iyz="6.35895367238167E-08"
        izz="0.000146738274500728" />
    </inertial>
    <visual>
      <origin
        xyz="0 0 0"
        rpy="0 0 0" />
      <geometry>
        <mesh
          filename="package://SUBO3/meshes/L_TORQUE_SENSOR_LINK.STL" />
      </geometry>
      <material
        name="">
        <color
          rgba="0.556862745098039 0.556862745098039 0.556862745098039 1" />
      </material>
    </visual>
    <collision>
      <origin
        xyz="0 0 0"
        rpy="0 0 0" />
      <geometry>
        <mesh
          filename="package://SUBO3/meshes/L_TORQUE_SENSOR_LINK.STL" />
      </geometry>
    </collision>
  </link>
  <joint
    name="L_TORQUE_SENSOR_JOINT"
    type="continuous">
    <origin
      xyz="0.062 0 -0.067"
      rpy="0 0 0" />
    <parent
      link="L_ANKLE_ROLL_LINK" />
    <child
      link="L_TORQUE_SENSOR_LINK" />
    <axis
      xyz="0 0 0" />
  </joint>
  <link
    name="L_FOOTPAD_LINK">
    <inertial>
      <origin
        xyz="0.0238493350962949 -0.0101823760192588 -0.00333012649439601"
        rpy="0 0 0" />
      <mass
        value="0.396271908798255" />
      <inertia
        ixx="0.000513049717026738"
        ixy="-6.00567113688711E-07"
        ixz="-2.3829615486034E-06"
        iyy="0.00117886868707081"
        iyz="2.76277685490073E-07"
        izz="0.00168027148383185" />
    </inertial>
    <visual>
      <origin
        xyz="0 0 0"
        rpy="0 0 0" />
      <geometry>
        <mesh
          filename="package://SUBO3/meshes/L_FOOTPAD_LINK.STL" />
      </geometry>
      <material
        name="">
        <color
          rgba="0.752941176470588 0.752941176470588 0.752941176470588 1" />
      </material>
    </visual>
    <collision>
      <origin
        xyz="0 0 0"
        rpy="0 0 0" />
      <geometry>
        <mesh
          filename="package://SUBO3/meshes/L_FOOTPAD_LINK.STL" />
      </geometry>
    </collision>
  </link>
  <joint
    name="L_FOOTPAD_JOINT"
    type="continuous">
    <origin
      xyz="0 0 -0.024"
      rpy="0 0 0" />
    <parent
      link="L_TORQUE_SENSOR_LINK" />
    <child
      link="L_FOOTPAD_LINK" />
    <axis
      xyz="0 0 0" />
  </joint>
  <link
    name="L_LEG_IMU_LINK">
    <inertial>
      <origin
        xyz="-0.000401989131834202 4.55636593020975E-05 0.00947601172535706"
        rpy="0 0 0" />
      <mass
        value="0.0368510660072014" />
      <inertia
        ixx="9.41068323673256E-06"
        ixy="-3.11242579613747E-08"
        ixz="-9.5193190026037E-08"
        iyy="9.157022531259E-06"
        iyz="1.07897197579416E-08"
        izz="1.61909985527922E-05" />
    </inertial>
    <visual>
      <origin
        xyz="0 0 0"
        rpy="0 0 0" />
      <geometry>
        <mesh
          filename="package://SUBO3/meshes/L_LEG_IMU_LINK.STL" />
      </geometry>
      <material
        name="">
        <color
          rgba="0.00784313725490196 0.454901960784314 0.0980392156862745 1" />
      </material>
    </visual>
    <collision>
      <origin
        xyz="0 0 0"
        rpy="0 0 0" />
      <geometry>
        <mesh
          filename="package://SUBO3/meshes/L_LEG_IMU_LINK.STL" />
      </geometry>
    </collision>
  </link>
  <joint
    name="L_LEG_IMU_JOINT"
    type="continuous">
    <origin
      xyz="0.0785 0 0.003"
      rpy="0 0 0" />
    <parent
      link="L_FOOTPAD_LINK" />
    <child
      link="L_LEG_IMU_LINK" />
    <axis
      xyz="0 0 0" />
  </joint>
  <link
    name="BODY_IMU_LINK">
    <inertial>
      <origin
        xyz="0.000401989131834247 4.55636593021357E-05 0.009476011725357"
        rpy="0 0 0" />
      <mass
        value="0.0368510660072013" />
      <inertia
        ixx="9.41068323673255E-06"
        ixy="3.11242579613755E-08"
        ixz="9.51931900260351E-08"
        iyy="9.15702253125899E-06"
        iyz="1.0789719757941E-08"
        izz="1.61909985527921E-05" />
    </inertial>
    <visual>
      <origin
        xyz="0 0 0"
        rpy="0 0 0" />
      <geometry>
        <mesh
          filename="package://SUBO3/meshes/BODY_IMU_LINK.STL" />
      </geometry>
      <material
        name="">
        <color
          rgba="0.00784313725490196 0.454901960784314 0.0980392156862745 1" />
      </material>
    </visual>
    <collision>
      <origin
        xyz="0 0 0"
        rpy="0 0 0" />
      <geometry>
        <mesh
          filename="package://SUBO3/meshes/BODY_IMU_LINK.STL" />
      </geometry>
    </collision>
  </link>
  <joint
    name="BODY_IMU_JOINT"
    type="continuous">
    <origin
      xyz="0.0015 0 -0.054"
      rpy="0 0 0" />
    <parent
      link="PELVIS_LINK" />
    <child
      link="BODY_IMU_LINK" />
    <axis
      xyz="0 0 0" />
  </joint>
</robot>