<?xml version="1.0" encoding="utf-8"?>
<!-- This URDF was automatically created by SolidWorks to URDF Exporter! Originally created by Stephen Brawner (brawner@gmail.com) 
     Commit Version: 1.6.0-1-g15f4949  Build Version: 1.6.7594.29634
     For more information, please see http://wiki.ros.org/sw_urdf_exporter -->
<robot
  name="SUBO3">
  <link
    name="UPPER_BODY_LINK">
    <inertial>
      <origin
        xyz="-0.0012216515614057 0.000363407264613957 0.0633769626572288"
        rpy="0 0 0" />
      <mass
        value="5.9955840020323" />
      <inertia
        ixx="0.0613726658563002"
        ixy="-2.25602848869656E-05"
        ixz="0.000720701414434317"
        iyy="0.0351768007447016"
        iyz="-0.000583087667878144"
        izz="0.0508003486042553" />
    </inertial>
    <visual>
      <origin
        xyz="0 0 0"
        rpy="0 0 0" />
      <geometry>
        <mesh
          filename="package://SUBO3/meshes/UPPER_BODY_LINK.STL" />
      </geometry>
      <material
        name="">
        <color
          rgba="0.752941176470588 0.752941176470588 0.752941176470588 1" />
      </material>
    </visual>
    <collision>
      <origin
        xyz="0 0 0"
        rpy="0 0 0" />
      <geometry>
        <mesh
          filename="package://SUBO3/meshes/UPPER_BODY_LINK.STL" />
      </geometry>
    </collision>
  </link>
  <link
    name="PELVIS_LINK">
    <inertial>
      <origin
        xyz="-0.015396539382622 -3.71881946220794E-06 -0.0238287293571032"
        rpy="0 0 0" />
      <mass
        value="2.40743071856051" />
      <inertia
        ixx="0.0101703545813297"
        ixy="-1.48065743492289E-06"
        ixz="9.20509062224505E-05"
        iyy="0.00371613605382298"
        iyz="3.90966895739273E-07"
        izz="0.0108266545059096" />
    </inertial>
    <visual>
      <origin
        xyz="0 0 0"
        rpy="0 0 0" />
      <geometry>
        <mesh
          filename="package://SUBO3/meshes/PELVIS_LINK.STL" />
      </geometry>
      <material
        name="">
        <color
          rgba="0.752941176470588 0.752941176470588 0.752941176470588 1" />
      </material>
    </visual>
    <collision>
      <origin
        xyz="0 0 0"
        rpy="0 0 0" />
      <geometry>
        <mesh
          filename="package://SUBO3/meshes/PELVIS_LINK.STL" />
      </geometry>
    </collision>
  </link>
  <joint
    name="PELVIS_JOINT"
    type="continuous">
    <origin
      xyz="0.021036 0 -0.04"
      rpy="0 0 0" />
    <parent
      link="UPPER_BODY_LINK" />
    <child
      link="PELVIS_LINK" />
    <axis
      xyz="0 0 0" />
  </joint>
  <link
    name="R_PELVIS_YAW_LINK">
    <inertial>
      <origin
        xyz="-0.0265992174097636 0.00621733561950238 -0.0280670157677253"
        rpy="0 0 0" />
      <mass
        value="0.529177042283365" />
      <inertia
        ixx="0.000418436362803154"
        ixy="-5.71520135782957E-06"
        ixz="-0.000133777282387252"
        iyy="0.000997903435296155"
        iyz="-1.78719207361946E-05"
        izz="0.000817579542112976" />
    </inertial>
    <visual>
      <origin
        xyz="0 0 0"
        rpy="0 0 0" />
      <geometry>
        <mesh
          filename="package://SUBO3/meshes/R_PELVIS_YAW_LINK.STL" />
      </geometry>
      <material
        name="">
        <color
          rgba="0.752941176470588 0.752941176470588 0.752941176470588 1" />
      </material>
    </visual>
    <collision>
      <origin
        xyz="0 0 0"
        rpy="0 0 0" />
      <geometry>
        <mesh
          filename="package://SUBO3/meshes/R_PELVIS_YAW_LINK.STL" />
      </geometry>
    </collision>
  </link>
  <joint
    name="R_PELVIS_YAW_JOINT"
    type="continuous">
    <origin
      xyz="0 -0.07 -0.075"
      rpy="0 0 0" />
    <parent
      link="PELVIS_LINK" />
    <child
      link="R_PELVIS_YAW_LINK" />
    <axis
      xyz="0 0 -1" />
  </joint>
  <link
    name="R_PELVIS_ROLL_LINK">
    <inertial>
      <origin
        xyz="0.0436595716549451 -0.0133299225119321 -2.51333295255285E-05"
        rpy="0 0 0" />
      <mass
        value="0.912484667273742" />
      <inertia
        ixx="0.000746583327912559"
        ixy="0.000218625717124258"
        ixz="-1.83821114708643E-06"
        iyy="0.00106600610511238"
        iyz="-1.11196448498131E-06"
        izz="0.00141402720848758" />
    </inertial>
    <visual>
      <origin
        xyz="0 0 0"
        rpy="0 0 0" />
      <geometry>
        <mesh
          filename="package://SUBO3/meshes/R_PELVIS_ROLL_LINK.STL" />
      </geometry>
      <material
        name="">
        <color
          rgba="0.752941176470588 0.752941176470588 0.752941176470588 1" />
      </material>
    </visual>
    <collision>
      <origin
        xyz="0 0 0"
        rpy="0 0 0" />
      <geometry>
        <mesh
          filename="package://SUBO3/meshes/R_PELVIS_ROLL_LINK.STL" />
      </geometry>
    </collision>
  </link>
  <joint
    name="R_PELVIS_ROLL_JOINT"
    type="continuous">
    <origin
      xyz="-0.06225 0 -0.074"
      rpy="0 0 0" />
    <parent
      link="R_PELVIS_YAW_LINK" />
    <child
      link="R_PELVIS_ROLL_LINK" />
    <axis
      xyz="-1 0 0" />
  </joint>
  <link
    name="R_PELVIS_PITCH_LINK">
    <inertial>
      <origin
        xyz="0.00348055748916328 0.0289538877155813 -0.164113937356433"
        rpy="0 0 0" />
      <mass
        value="1.89557769383052" />
      <inertia
        ixx="0.0158729931462636"
        ixy="-2.09058863496042E-05"
        ixz="1.16679733918345E-05"
        iyy="0.0144274582658531"
        iyz="-0.0007634452591894"
        izz="0.00279197908597204" />
    </inertial>
    <visual>
      <origin
        xyz="0 0 0"
        rpy="0 0 0" />
      <geometry>
        <mesh
          filename="package://SUBO3/meshes/R_PELVIS_PITCH_LINK.STL" />
      </geometry>
      <material
        name="">
        <color
          rgba="0.752941176470588 0.752941176470588 0.752941176470588 1" />
      </material>
    </visual>
    <collision>
      <origin
        xyz="0 0 0"
        rpy="0 0 0" />
      <geometry>
        <mesh
          filename="package://SUBO3/meshes/R_PELVIS_PITCH_LINK.STL" />
      </geometry>
    </collision>
  </link>
  <joint
    name="R_PELVIS_PITCH_JOINT"
    type="continuous">
    <origin
      xyz="0.062 -0.049 0"
      rpy="0 0 0" />
    <parent
      link="R_PELVIS_ROLL_LINK" />
    <child
      link="R_PELVIS_PITCH_LINK" />
    <axis
      xyz="0 -1 0" />
  </joint>
  <link
    name="R_KNEE_PITCH_LINK">
    <inertial>
      <origin
        xyz="0.000102280959906415 0.031018331983843 -0.14903551367948"
        rpy="0 0 0" />
      <mass
        value="1.35674558412184" />
      <inertia
        ixx="0.0135634436007511"
        ixy="-1.61006206751174E-05"
        ixz="-4.07674895554903E-05"
        iyy="0.0124663927754374"
        iyz="-0.00136511582684167"
        izz="0.0019479497524284" />
    </inertial>
    <visual>
      <origin
        xyz="0 0 0"
        rpy="0 0 0" />
      <geometry>
        <mesh
          filename="package://SUBO3/meshes/R_KNEE_PITCH_LINK.STL" />
      </geometry>
      <material
        name="">
        <color
          rgba="0.752941176470588 0.752941176470588 0.752941176470588 1" />
      </material>
    </visual>
    <collision>
      <origin
        xyz="0 0 0"
        rpy="0 0 0" />
      <geometry>
        <mesh
          filename="package://SUBO3/meshes/R_KNEE_PITCH_LINK.STL" />
      </geometry>
    </collision>
  </link>
  <joint
    name="R_KNEE_PITCH_JOINT"
    type="continuous">
    <origin
      xyz="0 0 -0.25"
      rpy="0 0 0" />
    <parent
      link="R_PELVIS_PITCH_LINK" />
    <child
      link="R_KNEE_PITCH_LINK" />
    <axis
      xyz="0 -1 0" />
  </joint>
  <link
    name="R_ANKLE_PITCH_LINK">
    <inertial>
      <origin
        xyz="-0.0195400857489775 0.0561075289377579 0.0147232730787041"
        rpy="0 0 0" />
      <mass
        value="0.840739094591803" />
      <inertia
        ixx="0.000693771202307297"
        ixy="-9.00503570275284E-05"
        ixz="-0.000112254129197613"
        iyy="0.00135466357852651"
        iyz="-9.64993557293776E-05"
        izz="0.001042416417298" />
    </inertial>
    <visual>
      <origin
        xyz="0 0 0"
        rpy="0 0 0" />
      <geometry>
        <mesh
          filename="package://SUBO3/meshes/R_ANKLE_PITCH_LINK.STL" />
      </geometry>
      <material
        name="">
        <color
          rgba="0.752941176470588 0.752941176470588 0.752941176470588 1" />
      </material>
    </visual>
    <collision>
      <origin
        xyz="0 0 0"
        rpy="0 0 0" />
      <geometry>
        <mesh
          filename="package://SUBO3/meshes/R_ANKLE_PITCH_LINK.STL" />
      </geometry>
    </collision>
  </link>
  <joint
    name="R_ANKLE_PITCH_JOINT"
    type="continuous">
    <origin
      xyz="0 0 -0.25"
      rpy="0 0 0" />
    <parent
      link="R_KNEE_PITCH_LINK" />
    <child
      link="R_ANKLE_PITCH_LINK" />
    <axis
      xyz="0 1 0" />
  </joint>
  <link
    name="R_ANKLE_ROLL_LINK">
    <inertial>
      <origin
        xyz="0.051907223777426 1.19348975147204E-15 -0.0264500245181483"
        rpy="0 0 0" />
      <mass
        value="0.274125500095123" />
      <inertia
        ixx="0.000225695352794552"
        ixy="2.15275541127049E-17"
        ixz="6.97268513865446E-05"
        iyy="0.000785347726778681"
        iyz="-2.13937229070387E-17"
        izz="0.000665543446844135" />
    </inertial>
    <visual>
      <origin
        xyz="0 0 0"
        rpy="0 0 0" />
      <geometry>
        <mesh
          filename="package://SUBO3/meshes/R_ANKLE_ROLL_LINK.STL" />
      </geometry>
      <material
        name="">
        <color
          rgba="0.752941176470588 0.752941176470588 0.752941176470588 1" />
      </material>
    </visual>
    <collision>
      <origin
        xyz="0 0 0"
        rpy="0 0 0" />
      <geometry>
        <mesh
          filename="package://SUBO3/meshes/R_ANKLE_ROLL_LINK.STL" />
      </geometry>
    </collision>
  </link>
  <joint
    name="R_ANKLE_ROLL_JOINT"
    type="continuous">
    <origin
      xyz="-0.061 0.049 0"
      rpy="0 0 0" />
    <parent
      link="R_ANKLE_PITCH_LINK" />
    <child
      link="R_ANKLE_ROLL_LINK" />
    <axis
      xyz="-1 0 0" />
  </joint>
  <link
    name="R_TORQUE_SENSOR_LINK">
    <inertial>
      <origin
        xyz="-0.00021106 -0.00036556 -0.0073766"
        rpy="0 0 0" />
      <mass
        value="0.1537" />
      <inertia
        ixx="8.3995E-05"
        ixy="1.0297E-06"
        ixz="3.7135E-08"
        iyy="8.5183E-05"
        iyz="6.359E-08"
        izz="0.00014674" />
    </inertial>
    <visual>
      <origin
        xyz="0 0 0"
        rpy="0 0 0" />
      <geometry>
        <mesh
          filename="package://SUBO3/meshes/R_TORQUE_SENSOR_LINK.STL" />
      </geometry>
      <material
        name="">
        <color
          rgba="0.55686 0.55686 0.55686 1" />
      </material>
    </visual>
    <collision>
      <origin
        xyz="0 0 0"
        rpy="0 0 0" />
      <geometry>
        <mesh
          filename="package://SUBO3/meshes/R_TORQUE_SENSOR_LINK.STL" />
      </geometry>
    </collision>
  </link>
  <joint
    name="R_TORQUE_SENSOR_JOINT"
    type="continuous">
    <origin
      xyz="0.062 0 -0.067"
      rpy="0 0 0" />
    <parent
      link="R_ANKLE_ROLL_LINK" />
    <child
      link="R_TORQUE_SENSOR_LINK" />
    <axis
      xyz="0 0 0" />
  </joint>
  <link
    name="R_FOOTPAD_LINK">
    <inertial>
      <origin
        xyz="0.023849 -0.010182 -0.0033301"
        rpy="0 0 0" />
      <mass
        value="0.39627" />
      <inertia
        ixx="0.00051305"
        ixy="-6.0057E-07"
        ixz="-2.383E-06"
        iyy="0.0011789"
        iyz="2.7628E-07"
        izz="0.0016803" />
    </inertial>
    <visual>
      <origin
        xyz="0 0 0"
        rpy="0 0 0" />
      <geometry>
        <mesh
          filename="package://SUBO3/meshes/R_FOOTPAD_LINK.STL" />
      </geometry>
      <material
        name="">
        <color
          rgba="0.75294 0.75294 0.75294 1" />
      </material>
    </visual>
    <collision>
      <origin
        xyz="0 0 0"
        rpy="0 0 0" />
      <geometry>
        <mesh
          filename="package://SUBO3/meshes/R_FOOTPAD_LINK.STL" />
      </geometry>
    </collision>
  </link>
  <joint
    name="R_FOOTPAD_JOINT"
    type="continuous">
    <origin
      xyz="0 0 -0.024"
      rpy="0 0 0" />
    <parent
      link="R_TORQUE_SENSOR_LINK" />
    <child
      link="R_FOOTPAD_LINK" />
    <axis
      xyz="0 0 0" />
  </joint>
  <link
    name="R_LEG_IMU_LINK">
    <inertial>
      <origin
        xyz="-0.00040199 4.5564E-05 0.009476"
        rpy="0 0 0" />
      <mass
        value="0.036851" />
      <inertia
        ixx="9.4107E-06"
        ixy="-3.1124E-08"
        ixz="-9.5193E-08"
        iyy="9.157E-06"
        iyz="1.079E-08"
        izz="1.6191E-05" />
    </inertial>
    <visual>
      <origin
        xyz="0 0 0"
        rpy="0 0 0" />
      <geometry>
        <mesh
          filename="package://SUBO3/meshes/R_LEG_IMU_LINK.STL" />
      </geometry>
      <material
        name="">
        <color
          rgba="0.0078431 0.4549 0.098039 1" />
      </material>
    </visual>
    <collision>
      <origin
        xyz="0 0 0"
        rpy="0 0 0" />
      <geometry>
        <mesh
          filename="package://SUBO3/meshes/R_LEG_IMU_LINK.STL" />
      </geometry>
    </collision>
  </link>
  <joint
    name="R_LEG_IMU_JOINT"
    type="continuous">
    <origin
      xyz="0.0785 0 0.003"
      rpy="0 0 0" />
    <parent
      link="R_FOOTPAD_LINK" />
    <child
      link="R_LEG_IMU_LINK" />
    <axis
      xyz="0 0 0" />
  </joint>
  <link
    name="L_PELVIS_YAW_LINK">
    <inertial>
      <origin
        xyz="-0.0266185656039676 -0.00622707166856507 -0.0280687606149806"
        rpy="0 0 0" />
      <mass
        value="0.530103422401833" />
      <inertia
        ixx="0.000418701653694017"
        ixy="5.23977335923569E-06"
        ixz="-0.00013315026797227"
        iyy="0.00100078253431412"
        iyz="1.79739812482646E-05"
        izz="0.00082040013756644" />
    </inertial>
    <visual>
      <origin
        xyz="0 0 0"
        rpy="0 0 0" />
      <geometry>
        <mesh
          filename="package://SUBO3/meshes/L_PELVIS_YAW_LINK.STL" />
      </geometry>
      <material
        name="">
        <color
          rgba="0.752941176470588 0.752941176470588 0.752941176470588 1" />
      </material>
    </visual>
    <collision>
      <origin
        xyz="0 0 0"
        rpy="0 0 0" />
      <geometry>
        <mesh
          filename="package://SUBO3/meshes/L_PELVIS_YAW_LINK.STL" />
      </geometry>
    </collision>
  </link>
  <joint
    name="L_PELVIS_YAW_JOINT"
    type="continuous">
    <origin
      xyz="0 0.07 -0.0749999999999993"
      rpy="0 0 0" />
    <parent
      link="PELVIS_LINK" />
    <child
      link="L_PELVIS_YAW_LINK" />
    <axis
      xyz="0 0 -1" />
  </joint>
  <link
    name="L_PELVIS_ROLL_LINK">
    <inertial>
      <origin
        xyz="0.0441278803367943 0.0129477028033571 -2.47634558976917E-05"
        rpy="0 0 0" />
      <mass
        value="0.92743824929528" />
      <inertia
        ixx="0.000758048909363523"
        ixy="-0.000210153504075411"
        ixz="-1.84684375815911E-06"
        iyy="0.00108289418445778"
        iyz="1.1235046850742E-06"
        izz="0.00144180362413627" />
    </inertial>
    <visual>
      <origin
        xyz="0 0 0"
        rpy="0 0 0" />
      <geometry>
        <mesh
          filename="package://SUBO3/meshes/L_PELVIS_ROLL_LINK.STL" />
      </geometry>
      <material
        name="">
        <color
          rgba="0.752941176470588 0.752941176470588 0.752941176470588 1" />
      </material>
    </visual>
    <collision>
      <origin
        xyz="0 0 0"
        rpy="0 0 0" />
      <geometry>
        <mesh
          filename="package://SUBO3/meshes/L_PELVIS_ROLL_LINK.STL" />
      </geometry>
    </collision>
  </link>
  <joint
    name="L_PELVIS_ROLL_JOINT"
    type="continuous">
    <origin
      xyz="-0.06225 0 -0.0740000000000006"
      rpy="0 0 0" />
    <parent
      link="L_PELVIS_YAW_LINK" />
    <child
      link="L_PELVIS_ROLL_LINK" />
    <axis
      xyz="1 0 0" />
  </joint>
  <link
    name="L_PELVIS_PITCH_LINK">
    <inertial>
      <origin
        xyz="0.00347793276601766 -0.0289423896739872 -0.164121798566548"
        rpy="0 0 0" />
      <mass
        value="1.89700617762081" />
      <inertia
        ixx="0.0158855319844667"
        ixy="2.09818326292223E-05"
        ixz="1.16191182682999E-05"
        iyy="0.0144388634205361"
        iyz="0.000760649193413026"
        izz="0.00279316672821379" />
    </inertial>
    <visual>
      <origin
        xyz="0 0 0"
        rpy="0 0 0" />
      <geometry>
        <mesh
          filename="package://SUBO3/meshes/L_PELVIS_PITCH_LINK.STL" />
      </geometry>
      <material
        name="">
        <color
          rgba="0.752941176470588 0.752941176470588 0.752941176470588 1" />
      </material>
    </visual>
    <collision>
      <origin
        xyz="0 0 0"
        rpy="0 0 0" />
      <geometry>
        <mesh
          filename="package://SUBO3/meshes/L_PELVIS_PITCH_LINK.STL" />
      </geometry>
    </collision>
  </link>
  <joint
    name="L_PELVIS_PITCH_JOINT"
    type="continuous">
    <origin
      xyz="0.0619999999999414 0.0489999999999982 0"
      rpy="0 0 0" />
    <parent
      link="L_PELVIS_ROLL_LINK" />
    <child
      link="L_PELVIS_PITCH_LINK" />
    <axis
      xyz="0 -1 0" />
  </joint>
  <link
    name="L_KNEE_PITCH_LINK">
    <inertial>
      <origin
        xyz="9.34122474958998E-05 -0.0310025846265913 -0.149105582466738"
        rpy="0 0 0" />
      <mass
        value="1.35813128156541" />
      <inertia
        ixx="0.013573619733379"
        ixy="1.66317396731267E-05"
        ixz="-4.0882859894528E-05"
        iyy="0.0124759094028436"
        iyz="0.00136528284806053"
        izz="0.00194922120905414" />
    </inertial>
    <visual>
      <origin
        xyz="0 0 0"
        rpy="0 0 0" />
      <geometry>
        <mesh
          filename="package://SUBO3/meshes/L_KNEE_PITCH_LINK.STL" />
      </geometry>
      <material
        name="">
        <color
          rgba="0.752941176470588 0.752941176470588 0.752941176470588 1" />
      </material>
    </visual>
    <collision>
      <origin
        xyz="0 0 0"
        rpy="0 0 0" />
      <geometry>
        <mesh
          filename="package://SUBO3/meshes/L_KNEE_PITCH_LINK.STL" />
      </geometry>
    </collision>
  </link>
  <joint
    name="L_KNEE_PITCH_JOINT"
    type="continuous">
    <origin
      xyz="0 0 -0.25"
      rpy="0 0 0" />
    <parent
      link="L_PELVIS_PITCH_LINK" />
    <child
      link="L_KNEE_PITCH_LINK" />
    <axis
      xyz="0 -1 0" />
  </joint>
  <link
    name="L_ANKLE_PITCH_LINK">
    <inertial>
      <origin
        xyz="-0.0194619959438271 -0.0561132801175172 0.0147291423287906"
        rpy="0 0 0" />
      <mass
        value="0.841930312664941" />
      <inertia
        ixx="0.000694257643204936"
        ixy="9.0307897109758E-05"
        ixz="-0.000112520382040985"
        iyy="0.00135865103457668"
        iyz="9.66067645916228E-05"
        izz="0.00104600194714616" />
    </inertial>
    <visual>
      <origin
        xyz="0 0 0"
        rpy="0 0 0" />
      <geometry>
        <mesh
          filename="package://SUBO3/meshes/L_ANKLE_PITCH_LINK.STL" />
      </geometry>
      <material
        name="">
        <color
          rgba="0.752941176470588 0.752941176470588 0.752941176470588 1" />
      </material>
    </visual>
    <collision>
      <origin
        xyz="0 0 0"
        rpy="0 0 0" />
      <geometry>
        <mesh
          filename="package://SUBO3/meshes/L_ANKLE_PITCH_LINK.STL" />
      </geometry>
    </collision>
  </link>
  <joint
    name="L_ANKLE_PITCH_JOINT"
    type="continuous">
    <origin
      xyz="0 0 -0.250000000000001"
      rpy="0 0 0" />
    <parent
      link="L_KNEE_PITCH_LINK" />
    <child
      link="L_ANKLE_PITCH_LINK" />
    <axis
      xyz="0 1 0" />
  </joint>
  <link
    name="L_ANKLE_ROLL_LINK">
    <inertial>
      <origin
        xyz="0.0519072237773094 9.43689570931383E-16 -0.0264500245181195"
        rpy="0 0 0" />
      <mass
        value="0.274125500097104" />
      <inertia
        ixx="0.000225695352796776"
        ixy="-2.88090470274889E-17"
        ixz="6.97268513881202E-05"
        iyy="0.000785347726786843"
        iyz="3.60241132085405E-17"
        izz="0.000665543446851336" />
    </inertial>
    <visual>
      <origin
        xyz="0 0 0"
        rpy="0 0 0" />
      <geometry>
        <mesh
          filename="package://SUBO3/meshes/L_ANKLE_ROLL_LINK.STL" />
      </geometry>
      <material
        name="">
        <color
          rgba="0.752941176470588 0.752941176470588 0.752941176470588 1" />
      </material>
    </visual>
    <collision>
      <origin
        xyz="0 0 0"
        rpy="0 0 0" />
      <geometry>
        <mesh
          filename="package://SUBO3/meshes/L_ANKLE_ROLL_LINK.STL" />
      </geometry>
    </collision>
  </link>
  <joint
    name="L_ANKLE_ROLL_JOINT"
    type="continuous">
    <origin
      xyz="-0.061 -0.049 0"
      rpy="0 0 0" />
    <parent
      link="L_ANKLE_PITCH_LINK" />
    <child
      link="L_ANKLE_ROLL_LINK" />
    <axis
      xyz="1 0 0" />
  </joint>
  <link
    name="L_TORQUE_SENSOR_LINK">
    <inertial>
      <origin
        xyz="0.00042203206883704 -4.2112357434565E-08 -0.00737656803896969"
        rpy="0 0 0" />
      <mass
        value="0.153698480754066" />
      <inertia
        ixx="8.57779592808547E-05"
        ixy="-2.93975739279726E-10"
        ixz="-7.37448539826538E-08"
        iyy="8.34021600438917E-05"
        iyz="4.35545411006486E-10"
        izz="0.000146739613496137" />
    </inertial>
    <visual>
      <origin
        xyz="0 0 0"
        rpy="0 0 0" />
      <geometry>
        <mesh
          filename="package://SUBO3/meshes/L_TORQUE_SENSOR_LINK.STL" />
      </geometry>
      <material
        name="">
        <color
          rgba="0.556862745098039 0.556862745098039 0.556862745098039 1" />
      </material>
    </visual>
    <collision>
      <origin
        xyz="0 0 0"
        rpy="0 0 0" />
      <geometry>
        <mesh
          filename="package://SUBO3/meshes/L_TORQUE_SENSOR_LINK.STL" />
      </geometry>
    </collision>
  </link>
  <joint
    name="L_TORQUE_SENSOR_JOINT"
    type="continuous">
    <origin
      xyz="0.062 0 -0.067"
      rpy="0 0 0" />
    <parent
      link="L_ANKLE_ROLL_LINK" />
    <child
      link="L_TORQUE_SENSOR_LINK" />
    <axis
      xyz="0 0 0" />
  </joint>
  <link
    name="L_FOOTPAD_LINK">
    <inertial>
      <origin
        xyz="0.023846772409407 0.0101854780847907 -0.00327900727596731"
        rpy="0 0 0" />
      <mass
        value="0.389644381256944" />
      <inertia
        ixx="0.00049867478946717"
        ixy="6.00381907308716E-07"
        ixz="-2.38601358453471E-06"
        iyy="0.00113946165916835"
        iyz="-2.72583274330624E-07"
        izz="0.00162669448381451" />
    </inertial>
    <visual>
      <origin
        xyz="0 0 0"
        rpy="0 0 0" />
      <geometry>
        <mesh
          filename="package://SUBO3/meshes/L_FOOTPAD_LINK.STL" />
      </geometry>
      <material
        name="">
        <color
          rgba="0.752941176470588 0.752941176470588 0.752941176470588 1" />
      </material>
    </visual>
    <collision>
      <origin
        xyz="0 0 0"
        rpy="0 0 0" />
      <geometry>
        <mesh
          filename="package://SUBO3/meshes/L_FOOTPAD_LINK.STL" />
      </geometry>
    </collision>
  </link>
  <joint
    name="L_FOOTPAD_JOINT"
    type="continuous">
    <origin
      xyz="0 0 -0.024"
      rpy="0 0 0" />
    <parent
      link="L_TORQUE_SENSOR_LINK" />
    <child
      link="L_FOOTPAD_LINK" />
    <axis
      xyz="0 0 0" />
  </joint>
  <link
    name="L_LEG_IMU_LINK">
    <inertial>
      <origin
        xyz="0.000401989129829528 4.5563660172443E-05 0.00947601172535706"
        rpy="0 0 0" />
      <mass
        value="0.0368510660072014" />
      <inertia
        ixx="9.41068323673257E-06"
        ixy="3.1124257961373E-08"
        ixz="9.51931900260354E-08"
        iyy="9.15702253125902E-06"
        iyz="1.07897197579408E-08"
        izz="1.61909985527922E-05" />
    </inertial>
    <visual>
      <origin
        xyz="0 0 0"
        rpy="0 0 0" />
      <geometry>
        <mesh
          filename="package://SUBO3/meshes/L_LEG_IMU_LINK.STL" />
      </geometry>
      <material
        name="">
        <color
          rgba="0.00784313725490196 0.454901960784314 0.0980392156862745 1" />
      </material>
    </visual>
    <collision>
      <origin
        xyz="0 0 0"
        rpy="0 0 0" />
      <geometry>
        <mesh
          filename="package://SUBO3/meshes/L_LEG_IMU_LINK.STL" />
      </geometry>
    </collision>
  </link>
  <joint
    name="L_LEG_IMU_JOINT"
    type="continuous">
    <origin
      xyz="0.0785 0 0.003"
      rpy="0 0 0" />
    <parent
      link="L_FOOTPAD_LINK" />
    <child
      link="L_LEG_IMU_LINK" />
    <axis
      xyz="0 0 0" />
  </joint>
  <link
    name="BODY_IMU_LINK">
    <inertial>
      <origin
        xyz="0.000401989131834247 4.55636593021357E-05 0.009476011725357"
        rpy="0 0 0" />
      <mass
        value="0.0368510660072013" />
      <inertia
        ixx="9.41068323673255E-06"
        ixy="3.11242579613754E-08"
        ixz="9.51931900260351E-08"
        iyy="9.15702253125899E-06"
        iyz="1.0789719757941E-08"
        izz="1.61909985527922E-05" />
    </inertial>
    <visual>
      <origin
        xyz="0 0 0"
        rpy="0 0 0" />
      <geometry>
        <mesh
          filename="package://SUBO3/meshes/BODY_IMU_LINK.STL" />
      </geometry>
      <material
        name="">
        <color
          rgba="0.00784313725490196 0.454901960784314 0.0980392156862745 1" />
      </material>
    </visual>
    <collision>
      <origin
        xyz="0 0 0"
        rpy="0 0 0" />
      <geometry>
        <mesh
          filename="package://SUBO3/meshes/BODY_IMU_LINK.STL" />
      </geometry>
    </collision>
  </link>
  <joint
    name="BODY_IMU_JOINT"
    type="continuous">
    <origin
      xyz="0.0015 0 -0.054"
      rpy="0 0 0" />
    <parent
      link="PELVIS_LINK" />
    <child
      link="BODY_IMU_LINK" />
    <axis
      xyz="0 0 0" />
  </joint>
</robot>